Workbook

Sheet Charging Infrastructure
A1: Weekly Charging Infrastructure Check
A2: Week | B2: Building | C2: Total active charging ports | D2: 11kW ports | E2: 30kW ports
A3: Week 1 (1/10) | B3: C | C3: 29 | D3: 24 | E3: 5
A4: Week 2 (6/10) | B4: C | C4: 29 | D4: 24 | E4: 5
A5: Week 3 (13/10) | B5: C | C5: 29 | D5: 24 | E5: 5
A6: Week 4 (20/10) | B6: C | C6: 29 | D6: 24 | E6: 5
A7: Week 5 (27/10) | B7: C | C7: 29 | D7: 24 | E7: 5
A10: Week | B10: Building | C10: Total active charging ports | D10: 11kW ports | E10: 30kW ports
A11: Week 1 (1/10) | B11: J | C11: 27 | D11: 23 | E11: 4
A12: Week 2 (6/10) | B12: J | C12: 27 | D12: 23 | E12: 4
A13: Week 3 (13/10) | B13: J | C13: 27 | D13: 23 | E13: 4
A14: Week 4 (20/10) | B14: J | C14: 27 | D14: 23 | E14: 4
A15: Week 5 (27/10) | B15: J | C15: 27 | D15: 23 | E15: 4

Sheet C_Vehicles
B1: Building_C - Daily Vehicles Observation
A2: Week | B2: Date | C2: Weekday | D2: Time | E2: Building | F2: VF9 | G2: VF8 | H2: VFe34 | I2: VF5 | J2: VF3 | K2: VF6 | L2: VF7 | M2: Total EV cars | N2: Gasoline cars | O2: Gasoline cars parked in active CP slot | P2: Total cars
A3: Testing | B3: 45932 | C3: Thu | D3: 09:00–10:00 | E3: C | F3: 7 | G3: 10 | H3: 1 | I3: 3 | J3: 3 | K3: 2 | M3: =SUM(F3:L3) -> 26 | N3: 7 | O3: 1 | P3: =M3+N3 -> 33
D4: 14:00–15:00 | E4: C | F4: 6 | G4: 5 | H4: 3 | I4: 2 | J4: 3 | K4: 3 | M4: =SUM(F4:L4) -> 22 | N4: 12 | P4: =M4+N4 -> 34
B5: 45933 | C5: Fri | D5: 09:00–10:00 | E5: C | F5: 9 | G5: 18 | H5: 5 | I5: 4 | K5: 3 | L5: 1 | M5: =SUM(F5:L5) -> 40 | N5: 21 | O5: 2 | P5: =M5+N5 -> 61
D6: 14:00–15:00 | E6: C | F6: 6 | G6: 10 | H6: 5 | I6: 1 | J6: 2 | K6: 4 | M6: =SUM(F6:L6) -> 28 | N6: 18 | P6: =M6+N6 -> 46
B7: 45934 | C7: Sat | D7: 09:00–10:00 | E7: C | F7: 2 | G7: 4 | H7: 1 | I7: 1 | J7: 2 | L7: 1 | M7: =SUM(F7:L7) -> 11 | N7: 3 | O7: 1 | P7: =M7+N7 -> 14
D8: 14:00–15:00 | E8: C | F8: 1 | G8: 4 | H8: 1 | J8: 1 | K8: 1 | L8: 1 | M8: =SUM(F8:L8) -> 9 | N8: 4 | P8: =M8+N8 -> 13
B9: 45935 | C9: Sun | D9: 09:00–10:00 | E9: C | F9: 1 | G9: 3 | H9: 0 | J9: 1 | M9: =SUM(F9:L9) -> 5 | N9: 2 | P9: =M9+N9 -> 7
D10: 14:00–15:00 | E10: C | G10: 2 | H10: 1 | L10: 1 | M10: =SUM(F10:L10) -> 4 | N10: 1 | O10: 1 | P10: =M10+N10 -> 5
A11: W1 | B11: 45936 | C11: Mon | D11: 09:00–10:00 | E11: C | F11: 6 | G11: 10 | H11: 3 | I11: 3 | K11: 1 | L11: 2 | M11: =SUM(F11:L11) -> 25 | N11: 6 | P11: =M11+N11 -> 31
D12: 14:00–15:00 | E12: C | F12: 7 | G12: 8 | H12: 2 | I12: 2 | J12: 2 | K12: 1 | L12: 2 | M12: =SUM(F12:L12) -> 24 | N12: 7 | O12: 1 | P12: =M12+N12 -> 31
B13: 45937 | C13: Tue | D13: 09:00–10:00 | E13: C | F13: 6 | G13: 14 | H13: 5 | I13: 5 | J13: 1 | K13: 2 | L13: 1 | M13: =SUM(F13:L13) -> 34 | N13: 7 | P13: =M13+N13 -> 41
D14: 14:00–15:00 | E14: C | F14: 7 | G14: 12 | H14: 7 | I14: 2 | L14: 1 | M14: =SUM(F14:L14) -> 29 | N14: 8 | P14: =M14+N14 -> 37
B15: 45938 | C15: Wed | D15: 09:00–10:00 | E15: C | F15: 9 | G15: 18 | H15: 10 | I15: 2 | J15: 2 | K15: 1 | L15: 1 | M15: =SUM(F15:L15) -> 43 | N15: 18 | O15: 2 | P15: =M15+N15 -> 61
D16: 14:00–15:00 | E16: C | F16: 7 | G16: 15 | H16: 10 | I16: 2 | J16: 3 | K16: 1 | L16: 1 | M16: =SUM(F16:L16) -> 39 | N16: 12 | O16: 3 | P16: =M16+N16 -> 51
B17: 45939 | C17: Thu | D17: 09:00–10:00 | E17: C | F17: 5 | G17: 17 | H17: 10 | I17: 4 | J17: 3 | K17: 3 | L17: 2 | M17: =SUM(F17:L17) -> 44 | N17: 21 | O17: 9 | P17: =M17+N17 -> 65
D18: 14:00–15:00 | E18: C | F18: 7 | G18: 16 | H18: 7 | I18: 2 | J18: 1 | K18: 1 | L18: 1 | M18: =SUM(F18:L18) -> 35 | N18: 20 | O18: 5 | P18: =M18+N18 -> 55
B19: 45940 | C19: Fri | D19: 09:00–10:00 | E19: C | F19: 6 | G19: 12 | H19: 16 | I19: 1 | J19: 2 | L19: 2 | M19: =SUM(F19:L19) -> 39 | N19: 19 | O19: 3 | P19: =M19+N19 -> 58
D20: 14:00–15:00 | E20: C | F20: 7 | G20: 16 | H20: 18 | J20: 2 | K20: 2 | L20: 1 | M20: =SUM(F20:L20) -> 46 | N20: 26 | O20: 9 | P20: =M20+N20 -> 72
A21: W2 | B21: 45943 | C21: Mon | D21: 09:00–10:00 | E21: C | F21: 5 | G21: 12 | H21: 3 | I21: 4 | J21: 2 | L21: 2 | M21: =SUM(F21:L21) -> 28 | N21: 13 | O21: 2 | P21: =M21+N21 -> 41
D22: 14:00–15:00 | E22: C | F22: 7 | G22: 9 | H22: 2 | I22: 3 | K22: 1 | L22: 2 | M22: =SUM(F22:L22) -> 24 | N22: 9 | P22: =M22+N22 -> 33
B23: 45944 | C23: Tue | D23: 09:00–10:00 | E23: C | F23: 6 | G23: 14 | H23: 11 | I23: 3 | J23: 1 | K23: 3 | L23: 3 | M23: =SUM(F23:L23) -> 41 | N23: 25 | O23: 4 | P23: =M23+N23 -> 66
D24: 14:00–15:00 | E24: C | F24: 8 | G24: 14 | H24: 9 | I24: 2 | J24: 2 | K24: 4 | L24: 2 | M24: =SUM(F24:L24) -> 41 | N24: 24 | O24: 8 | P24: =M24+N24 -> 65
B25: 45945 | C25: Wed | D25: 09:00–10:00 | E25: C | F25: 8 | G25: 15 | H25: 7 | J25: 3 | L25: 1 | M25: =SUM(F25:L25) -> 34 | N25: 22 | O25: 5 | P25: =M25+N25 -> 56
D26: 14:00–15:00 | E26: C | F26: 7 | G26: 16 | H26: 4 | I26: 2 | J26: 1 | K26: 2 | M26: =SUM(F26:L26) -> 32 | N26: 21 | O26: 1 | P26: =M26+N26 -> 53
B27: 45946 | C27: Thu | D27: 09:00–10:00 | E27: C | F27: 6 | G27: 17 | H27: 2 | I27: 4 | J27: 3 | K27: 4 | L27: 1 | M27: =SUM(F27:L27) -> 37 | N27: 21 | O27: 6 | P27: =M27+N27 -> 58
D28: 14:00–15:00 | E28: C | F28: 9 | G28: 19 | H28: 2 | I28: 2 | J28: 1 | K28: 3 | M28: =SUM(F28:L28) -> 36 | N28: 20 | O28: 3 | P28: =M28+N28 -> 56
B29: 45947 | C29: Fri | D29: 09:00–10:00 | E29: C | F29: 7 | G29: 10 | H29: 16 | I29: 1 | J29: 3 | K29: 3 | L29: 1 | M29: =SUM(F29:L29) -> 41 | N29: 18 | P29: =M29+N29 -> 59
D30: 14:00–15:00 | E30: C | F30: 5 | G30: 14 | H30: 16 | J30: 2 | L30: 3 | M30: =SUM(F30:L30) -> 40 | N30: 24 | O30: 1 | P30: =M30+N30 -> 64
A31: W3 | B31: 45950 | C31: Mon | D31: 09:00–10:00 | E31: C | F31: 7 | G31: 12 | H31: 6 | I31: 5 | J31: 2 | K31: 1 | L31: 3 | M31: =SUM(F31:L31) -> 36 | N31: 15 | O31: 2 | P31: =M31+N31 -> 51
D32: 14:00–15:00 | E32: C | F32: 6 | G32: 11 | H32: 3 | I32: 4 | J32: 2 | K32: 1 | L32: 2 | M32: =SUM(F32:L32) -> 29 | N32: 11 | P32: =M32+N32 -> 40
B33: 45951 | C33: Tue | D33: 09:00–10:00 | E33: C | F33: 6 | G33: 15 | H33: 4 | I33: 3 | J33: 4 | L33: 1 | M33: =SUM(F33:L33) -> 33 | N33: 17 | O33: 1 | P33: =M33+N33 -> 50
D34: 14:00–15:00 | E34: C | F34: 6 | G34: 16 | H34: 4 | I34: 3 | J34: 3 | K34: 1 | L34: 3 | M34: =SUM(F34:L34) -> 36 | N34: 19 | O34: 1 | P34: =M34+N34 -> 55
B35: 45952 | C35: Wed | D35: 09:00–10:00 | E35: C | F35: 8 | G35: 15 | H35: 6 | I35: 2 | J35: 1 | K35: 2 | M35: =SUM(F35:L35) -> 34 | N35: 25 | P35: =M35+N35 -> 59
D36: 14:00–15:00 | E36: C | F36: 5 | G36: 17 | H36: 5 | I36: 4 | K36: 2 | L36: 1 | M36: =SUM(F36:L36) -> 34 | N36: 20 | P36: =M36+N36 -> 54
B37: 45953 | C37: Thu | D37: 09:00–10:00 | E37: C | F37: 5 | G37: 19 | H37: 2 | I37: 5 | J37: 3 | K37: 2 | L37: 1 | M37: =SUM(F37:L37) -> 37 | N37: 21 | O37: 7 | P37: =M37+N37 -> 58
D38: 14:00–15:00 | E38: C | F38: 5 | G38: 18 | H38: 4 | I38: 4 | J38: 1 | K38: 3 | L38: 2 | M38: =SUM(F38:L38) -> 37 | N38: 20 | O38: 4 | P38: =M38+N38 -> 57
B39: 45954 | C39: Fri | D39: 09:00–10:00 | E39: C | F39: 6 | G39: 12 | H39: 12 | I39: 4 | J39: 1 | K39: 2 | L39: 1 | M39: =SUM(F39:L39) -> 38 | N39: 3 | P39: =M39+N39 -> 41
D40: 14:00–15:00 | E40: C | F40: 4 | G40: 9 | H40: 10 | I40: 4 | K40: 2 | L40: 3 | M40: =SUM(F40:L40) -> 32 | N40: 4 | P40: =M40+N40 -> 36
...

Sheet J_Vehicles
B1: Building_J - Daily Vehicles Observation
A2: Week | B2: Date | C2: Weekday | D2: Time | E2: Building | F2: VF9 | G2: VF8 | H2: VFe34 | I2: VF5 | J2: VF3 | K2: VF6 | L2: VF7 | M2: Total EV cars | N2: Gasoline cars | O2: Gasoline cars parked in active CP slot | P2: Total cars
A3: Testing | B3: 45932 | C3: Thu | D3: 09:00–10:00 | E3: J | F3: 1 | G3: 6 | I3: 1 | M3: =SUM(F3:L3) -> 8 | N3: 10 | O3: 5 | P3: =M3+N3 -> 18
D4: 14:00–15:00 | E4: J | G4: 4 | H4: 1 | L4: 1 | M4: =SUM(F4:L4) -> 6 | N4: 11 | O4: 4 | P4: =M4+N4 -> 17
B5: 45933 | C5: Fri | D5: 09:00–10:00 | E5: J | F5: 1 | G5: 2 | H5: 3 | L5: 1 | M5: =SUM(F5:L5) -> 7 | N5: 16 | O5: 4 | P5: =M5+N5 -> 23
D6: 14:00–15:00 | E6: J | G6: 2 | H6: 2 | J6: 1 | M6: =SUM(F6:L6) -> 5 | N6: 13 | O6: 3 | P6: =M6+N6 -> 18
B7: 45934 | C7: Sat | D7: 09:00–10:00 | E7: J | G7: 3 | H7: 2 | K7: 1 | M7: =SUM(F7:L7) -> 6 | N7: 5 | P7: =M7+N7 -> 11
D8: 14:00–15:00 | E8: J | F8: 1 | G8: 2 | M8: =SUM(F8:L8) -> 3 | N8: 4 | O8: 1 | P8: =M8+N8 -> 7
B9: 45935 | C9: Sun | D9: 09:00–10:00 | E9: J | F9: 1 | G9: 2 | M9: =SUM(F9:L9) -> 3 | N9: 4 | P9: =M9+N9 -> 7
D10: 14:00–15:00 | E10: J | G10: 2 | J10: 1 | M10: =SUM(F10:L10) -> 3 | N10: 4 | P10: =M10+N10 -> 7
A11: W1 | B11: 45936 | C11: Mon | D11: 09:00–10:00 | E11: J | F11: 1 | G11: 10 | H11: 2 | J11: 1 | M11: =SUM(F11:L11) -> 14 | N11: 14 | O11: 13 | P11: =M11+N11 -> 28
D12: 14:00–15:00 | E12: J | F12: 2 | G12: 9 | J12: 1 | L12: 1 | M12: =SUM(F12:L12) -> 13 | N12: 13 | O12: 13 | P12: =M12+N12 -> 26
B13: 45937 | C13: Tue | D13: 09:00–10:00 | E13: J | F13: 1 | G13: 4 | H13: 2 | L13: 1 | M13: =SUM(F13:L13) -> 8 | N13: 15 | O13: 15 | P13: =M13+N13 -> 23
D14: 14:00–15:00 | E14: J | F14: 1 | G14: 4 | H14: 1 | L14: 1 | M14: =SUM(F14:L14) -> 7 | N14: 15 | O14: 15 | P14: =M14+N14 -> 22
B15: 45938 | C15: Wed | D15: 09:00–10:00 | E15: J | F15: 3 | G15: 4 | J15: 1 | L15: 1 | M15: =SUM(F15:L15) -> 9 | N15: 17 | O15: 10 | P15: =M15+N15 -> 26
D16: 14:00–15:00 | E16: J | F16: 2 | G16: 4 | J16: 1 | L16: 1 | M16: =SUM(F16:L16) -> 8 | N16: 18 | O16: 10 | P16: =M16+N16 -> 26
B17: 45939 | C17: Thu | D17: 09:00–10:00 | E17: J | F17: 1 | G17: 5 | H17: 2 | I17: 1 | L17: 2 | M17: =SUM(F17:L17) -> 11 | N17: 17 | O17: 9 | P17: =M17+N17 -> 28
D18: 14:00–15:00 | E18: J | F18: 2 | G18: 3 | H18: 3 | L18: 1 | M18: =SUM(F18:L18) -> 9 | N18: 16 | O18: 8 | P18: =M18+N18 -> 25
B19: 45940 | C19: Fri | D19: 09:00–10:00 | E19: J | F19: 3 | G19: 7 | H19: 4 | J19: 1 | K19: 2 | M19: =SUM(F19:L19) -> 17 | N19: 7 | O19: 4 | P19: =M19+N19 -> 24
D20: 14:00–15:00 | E20: J | F20: 4 | G20: 9 | H20: 5 | K20: 1 | M20: =SUM(F20:L20) -> 19 | N20: 6 | O20: 3 | P20: =M20+N20 -> 25
A21: W2 | B21: 45943 | C21: Mon | D21: 09:00–10:00 | E21: J | F21: 1 | G21: 4 | I21: 2 | K21: 1 | L21: 1 | M21: =SUM(F21:L21) -> 9 | N21: 11 | O21: 11 | P21: =M21+N21 -> 20
D22: 14:00–15:00 | E22: J | F22: 1 | G22: 3 | I22: 2 | K22: 1 | L22: 1 | M22: =SUM(F22:L22) -> 8 | N22: 9 | O22: 7 | P22: =M22+N22 -> 17
B23: 45944 | C23: Tue | D23: 09:00–10:00 | E23: J | F23: 1 | G23: 4 | H23: 2 | J23: 1 | K23: 2 | L23: 1 | M23: =SUM(F23:L23) -> 11 | N23: 12 | O23: 9 | P23: =M23+N23 -> 23
D24: 14:00–15:00 | E24: J | F24: 2 | G24: 6 | H24: 1 | J24: 1 | K24: 2 | L24: 2 | M24: =SUM(F24:L24) -> 14 | N24: 9 | O24: 9 | P24: =M24+N24 -> 23
B25: 45945 | C25: Wed | D25: 09:00–10:00 | E25: J | F25: 1 | G25: 5 | H25: 1 | I25: 1 | K25: 2 | L25: 2 | M25: =SUM(F25:L25) -> 12 | N25: 14 | O25: 14 | P25: =M25+N25 -> 26
D26: 14:00–15:00 | E26: J | F26: 1 | G26: 4 | M26: =SUM(F26:L26) -> 5 | N26: 14 | O26: 12 | P26: =M26+N26 -> 19
B27: 45946 | C27: Thu | D27: 09:00–10:00 | E27: J | F27: 2 | G27: 4 | H27: 2 | K27: 1 | M27: =SUM(F27:L27) -> 9 | N27: 16 | O27: 16 | P27: =M27+N27 -> 25
D28: 14:00–15:00 | E28: J | F28: 1 | G28: 3 | H28: 2 | J28: 1 | M28: =SUM(F28:L28) -> 7 | N28: 15 | O28: 15 | P28: =M28+N28 -> 22
B29: 45947 | C29: Fri | D29: 09:00–10:00 | E29: J | F29: 2 | G29: 3 | H29: 2 | J29: 1 | K29: 1 | M29: =SUM(F29:L29) -> 9 | N29: 16 | O29: 16 | P29: =M29+N29 -> 25
D30: 14:00–15:00 | E30: J | F30: 1 | G30: 2 | H30: 2 | J30: 1 | K30: 1 | L30: 1 | M30: =SUM(F30:L30) -> 8 | N30: 13 | O30: 13 | P30: =M30+N30 -> 21
A31: W3 | B31: 45950 | C31: Mon | D31: 09:00–10:00 | E31: J | F31: 4 | G31: 5 | H31: 1 | I31: 1 | L31: 1 | M31: =SUM(F31:L31) -> 12 | N31: 12 | O31: 12 | P31: =M31+N31 -> 24
D32: 14:00–15:00 | E32: J | F32: 3 | G32: 4 | H32: 1 | I32: 1 | M32: =SUM(F32:L32) -> 9 | N32: 12 | O32: 12 | P32: =M32+N32 -> 21
B33: 45951 | C33: Tue | D33: 09:00–10:00 | E33: J | F33: 1 | G33: 5 | H33: 1 | I33: 1 | J33: 1 | M33: =SUM(F33:L33) -> 9 | N33: 12 | O33: 12 | P33: =M33+N33 -> 21
D34: 14:00–15:00 | E34: J | F34: 1 | G34: 4 | J34: 1 | L34: 1 | M34: =SUM(F34:L34) -> 7 | N34: 12 | O34: 12 | P34: =M34+N34 -> 19
B35: 45952 | C35: Wed | D35: 09:00–10:00 | E35: J | F35: 2 | G35: 3 | J35: 1 | K35: 1 | M35: =SUM(F35:L35) -> 7 | N35: 15 | O35: 15 | P35: =M35+N35 -> 22
D36: 14:00–15:00 | E36: J | F36: 2 | G36: 4 | H36: 1 | K36: 1 | M36: =SUM(F36:L36) -> 8 | N36: 10 | O36: 9 | P36: =M36+N36 -> 18
B37: 45953 | C37: Thu | D37: 09:00–10:00 | E37: J | F37: 1 | G37: 5 | H37: 1 | J37: 1 | L37: 2 | M37: =SUM(F37:L37) -> 10 | N37: 14 | O37: 14 | P37: =M37+N37 -> 24
D38: 14:00–15:00 | E38: J | G38: 4 | H38: 1 | J38: 1 | L38: 2 | M38: =SUM(F38:L38) -> 8 | N38: 15 | O38: 15 | P38: =M38+N38 -> 23
B39: 45954 | C39: Fri | D39: 09:00–10:00 | E39: J | F39: 4 | G39: 4 | H39: 2 | I39: 1 | K39: 2 | M39: =SUM(F39:L39) -> 13 | N39: 5 | O39: 2 | P39: =M39+N39 -> 18
D40: 14:00–15:00 | E40: J | F40: 4 | G40: 5 | H40: 2 | I40: 1 | J40: 1 | K40: 2 | M40: =SUM(F40:L40) -> 15 | N40: 8 | O40: 2 | P40: =M40+N40 -> 23
...

Sheet All_Vehicles
B1: Building C&J - Daily Vehicles Observation
A2: Week | B2: Date | C2: Weekday | D2: Time | E2: Building | F2: VF9 | G2: VF8 | H2: VFe34 | I2: VF5 | J2: VF3 | K2: VF6 | L2: VF7 | M2: Total EV cars | N2: Gasoline cars | O2: Gasoline cars parked in active CP slot | P2: Total cars
A3: Testing | B3: 45932 | C3: Thu | D3: 09:00–10:00 | E3: C&J | F3: =C_Vehicles!F3+J_Vehicles!F3 -> 8 | G3: =C_Vehicles!G3+J_Vehicles!G3 -> 16 | H3: =C_Vehicles!H3+J_Vehicles!H3 -> 1 | I3: =C_Vehicles!I3+J_Vehicles!I3 -> 4 | J3: =C_Vehicles!J3+J_Vehicles!J3 -> 3 | K3: =C_Vehicles!K3+J_Vehicles!K3 -> 2 | L3: =C_Vehicles!L3+J_Vehicles!L3 -> 0 | M3: =SUM(F3:L3) -> 34 | N3: =C_Vehicles!N3+J_Vehicles!N3 -> 17 | O3: =C_Vehicles!O3+J_Vehicles!O3 -> 6 | P3: =M3+N3 -> 51
D4: 14:00–15:00 | E4: C&J | F4: =C_Vehicles!F4+J_Vehicles!F4 -> 6 | G4: =C_Vehicles!G4+J_Vehicles!G4 -> 9 | H4: =C_Vehicles!H4+J_Vehicles!H4 -> 4 | I4: =C_Vehicles!I4+J_Vehicles!I4 -> 2 | J4: =C_Vehicles!J4+J_Vehicles!J4 -> 3 | K4: =C_Vehicles!K4+J_Vehicles!K4 -> 3 | L4: =C_Vehicles!L4+J_Vehicles!L4 -> 1 | M4: =SUM(F4:L4) -> 28 | N4: =C_Vehicles!N4+J_Vehicles!N4 -> 23 | O4: =C_Vehicles!O4+J_Vehicles!O4 -> 4 | P4: =M4+N4 -> 51
B5: 45933 | C5: Fri | D5: 09:00–10:00 | E5: C&J | F5: =C_Vehicles!F5+J_Vehicles!F5 -> 10 | G5: =C_Vehicles!G5+J_Vehicles!G5 -> 20 | H5: =C_Vehicles!H5+J_Vehicles!H5 -> 8 | I5: =C_Vehicles!I5+J_Vehicles!I5 -> 4 | J5: =C_Vehicles!J5+J_Vehicles!J5 -> 0 | K5: =C_Vehicles!K5+J_Vehicles!K5 -> 3 | L5: =C_Vehicles!L5+J_Vehicles!L5 -> 2 | M5: =SUM(F5:L5) -> 47 | N5: =C_Vehicles!N5+J_Vehicles!N5 -> 37 | O5: =C_Vehicles!O5+J_Vehicles!O5 -> 6 | P5: =M5+N5 -> 84
D6: 14:00–15:00 | E6: C&J | F6: =C_Vehicles!F6+J_Vehicles!F6 -> 6 | G6: =C_Vehicles!G6+J_Vehicles!G6 -> 12 | H6: =C_Vehicles!H6+J_Vehicles!H6 -> 7 | I6: =C_Vehicles!I6+J_Vehicles!I6 -> 1 | J6: =C_Vehicles!J6+J_Vehicles!J6 -> 3 | K6: =C_Vehicles!K6+J_Vehicles!K6 -> 4 | L6: =C_Vehicles!L6+J_Vehicles!L6 -> 0 | M6: =SUM(F6:L6) -> 33 | N6: =C_Vehicles!N6+J_Vehicles!N6 -> 31 | O6: =C_Vehicles!O6+J_Vehicles!O6 -> 3 | P6: =M6+N6 -> 64
B7: 45934 | C7: Sat | D7: 09:00–10:00 | E7: C&J | F7: =C_Vehicles!F7+J_Vehicles!F7 -> 2 | G7: =C_Vehicles!G7+J_Vehicles!G7 -> 7 | H7: =C_Vehicles!H7+J_Vehicles!H7 -> 3 | I7: =C_Vehicles!I7+J_Vehicles!I7 -> 1 | J7: =C_Vehicles!J7+J_Vehicles!J7 -> 2 | K7: =C_Vehicles!K7+J_Vehicles!K7 -> 1 | L7: =C_Vehicles!L7+J_Vehicles!L7 -> 1 | M7: =SUM(F7:L7) -> 17 | N7: =C_Vehicles!N7+J_Vehicles!N7 -> 8 | O7: =C_Vehicles!O7+J_Vehicles!O7 -> 1 | P7: =M7+N7 -> 25
D8: 14:00–15:00 | E8: C&J | F8: =C_Vehicles!F8+J_Vehicles!F8 -> 2 | G8: =C_Vehicles!G8+J_Vehicles!G8 -> 6 | H8: =C_Vehicles!H8+J_Vehicles!H8 -> 1 | I8: =C_Vehicles!I8+J_Vehicles!I8 -> 0 | J8: =C_Vehicles!J8+J_Vehicles!J8 -> 1 | K8: =C_Vehicles!K8+J_Vehicles!K8 -> 1 | L8: =C_Vehicles!L8+J_Vehicles!L8 -> 1 | M8: =SUM(F8:L8) -> 12 | N8: =C_Vehicles!N8+J_Vehicles!N8 -> 8 | O8: =C_Vehicles!O8+J_Vehicles!O8 -> 1 | P8: =M8+N8 -> 20
B9: 45935 | C9: Sun | D9: 09:00–10:00 | E9: C&J | F9: =C_Vehicles!F9+J_Vehicles!F9 -> 2 | G9: =C_Vehicles!G9+J_Vehicles!G9 -> 5 | H9: =C_Vehicles!H9+J_Vehicles!H9 -> 0 | I9: =C_Vehicles!I9+J_Vehicles!I9 -> 0 | J9: =C_Vehicles!J9+J_Vehicles!J9 -> 1 | K9: =C_Vehicles!K9+J_Vehicles!K9 -> 0 | L9: =C_Vehicles!L9+J_Vehicles!L9 -> 0 | M9: =SUM(F9:L9) -> 8 | N9: =C_Vehicles!N9+J_Vehicles!N9 -> 6 | O9: =C_Vehicles!O9+J_Vehicles!O9 -> 0 | P9: =M9+N9 -> 14
D10: 14:00–15:00 | E10: C&J | F10: =C_Vehicles!F10+J_Vehicles!F10 -> 0 | G10: =C_Vehicles!G10+J_Vehicles!G10 -> 4 | H10: =C_Vehicles!H10+J_Vehicles!H10 -> 1 | I10: =C_Vehicles!I10+J_Vehicles!I10 -> 0 | J10: =C_Vehicles!J10+J_Vehicles!J10 -> 1 | K10: =C_Vehicles!K10+J_Vehicles!K10 -> 0 | L10: =C_Vehicles!L10+J_Vehicles!L10 -> 1 | M10: =SUM(F10:L10) -> 7 | N10: =C_Vehicles!N10+J_Vehicles!N10 -> 5 | O10: =C_Vehicles!O10+J_Vehicles!O10 -> 1 | P10: =M10+N10 -> 12
A11: W1 | B11: 45936 | C11: Mon | D11: 09:00–10:00 | E11: C&J | F11: =C_Vehicles!F11+J_Vehicles!F11 -> 7 | G11: =C_Vehicles!G11+J_Vehicles!G11 -> 20 | H11: =C_Vehicles!H11+J_Vehicles!H11 -> 5 | I11: =C_Vehicles!I11+J_Vehicles!I11 -> 3 | J11: =C_Vehicles!J11+J_Vehicles!J11 -> 1 | K11: =C_Vehicles!K11+J_Vehicles!K11 -> 1 | L11: =C_Vehicles!L11+J_Vehicles!L11 -> 2 | M11: =SUM(F11:L11) -> 39 | N11: =C_Vehicles!N11+J_Vehicles!N11 -> 20 | O11: =C_Vehicles!O11+J_Vehicles!O11 -> 13 | P11: =M11+N11 -> 59
D12: 14:00–15:00 | E12: C&J | F12: =C_Vehicles!F12+J_Vehicles!F12 -> 9 | G12: =C_Vehicles!G12+J_Vehicles!G12 -> 17 | H12: =C_Vehicles!H12+J_Vehicles!H12 -> 2 | I12: =C_Vehicles!I12+J_Vehicles!I12 -> 2 | J12: =C_Vehicles!J12+J_Vehicles!J12 -> 3 | K12: =C_Vehicles!K12+J_Vehicles!K12 -> 1 | L12: =C_Vehicles!L12+J_Vehicles!L12 -> 3 | M12: =SUM(F12:L12) -> 37 | N12: =C_Vehicles!N12+J_Vehicles!N12 -> 20 | O12: =C_Vehicles!O12+J_Vehicles!O12 -> 14 | P12: =M12+N12 -> 57
B13: 45937 | C13: Tue | D13: 09:00–10:00 | E13: C&J | F13: =C_Vehicles!F13+J_Vehicles!F13 -> 7 | G13: =C_Vehicles!G13+J_Vehicles!G13 -> 18 | H13: =C_Vehicles!H13+J_Vehicles!H13 -> 7 | I13: =C_Vehicles!I13+J_Vehicles!I13 -> 5 | J13: =C_Vehicles!J13+J_Vehicles!J13 -> 1 | K13: =C_Vehicles!K13+J_Vehicles!K13 -> 2 | L13: =C_Vehicles!L13+J_Vehicles!L13 -> 2 | M13: =SUM(F13:L13) -> 42 | N13: =C_Vehicles!N13+J_Vehicles!N13 -> 22 | O13: =C_Vehicles!O13+J_Vehicles!O13 -> 15 | P13: =M13+N13 -> 64
D14: 14:00–15:00 | E14: C&J | F14: =C_Vehicles!F14+J_Vehicles!F14 -> 8 | G14: =C_Vehicles!G14+J_Vehicles!G14 -> 16 | H14: =C_Vehicles!H14+J_Vehicles!H14 -> 8 | I14: =C_Vehicles!I14+J_Vehicles!I14 -> 2 | J14: =C_Vehicles!J14+J_Vehicles!J14 -> 0 | K14: =C_Vehicles!K14+J_Vehicles!K14 -> 0 | L14: =C_Vehicles!L14+J_Vehicles!L14 -> 2 | M14: =SUM(F14:L14) -> 36 | N14: =C_Vehicles!N14+J_Vehicles!N14 -> 23 | O14: =C_Vehicles!O14+J_Vehicles!O14 -> 15 | P14: =M14+N14 -> 59
B15: 45938 | C15: Wed | D15: 09:00–10:00 | E15: C&J | F15: =C_Vehicles!F15+J_Vehicles!F15 -> 12 | G15: =C_Vehicles!G15+J_Vehicles!G15 -> 22 | H15: =C_Vehicles!H15+J_Vehicles!H15 -> 10 | I15: =C_Vehicles!I15+J_Vehicles!I15 -> 2 | J15: =C_Vehicles!J15+J_Vehicles!J15 -> 3 | K15: =C_Vehicles!K15+J_Vehicles!K15 -> 1 | L15: =C_Vehicles!L15+J_Vehicles!L15 -> 2 | M15: =SUM(F15:L15) -> 52 | N15: =C_Vehicles!N15+J_Vehicles!N15 -> 35 | O15: =C_Vehicles!O15+J_Vehicles!O15 -> 12 | P15: =M15+N15 -> 87
D16: 14:00–15:00 | E16: C&J | F16: =C_Vehicles!F16+J_Vehicles!F16 -> 9 | G16: =C_Vehicles!G16+J_Vehicles!G16 -> 19 | H16: =C_Vehicles!H16+J_Vehicles!H16 -> 10 | I16: =C_Vehicles!I16+J_Vehicles!I16 -> 2 | J16: =C_Vehicles!J16+J_Vehicles!J16 -> 4 | K16: =C_Vehicles!K16+J_Vehicles!K16 -> 1 | L16: =C_Vehicles!L16+J_Vehicles!L16 -> 2 | M16: =SUM(F16:L16) -> 47 | N16: =C_Vehicles!N16+J_Vehicles!N16 -> 30 | O16: =C_Vehicles!O16+J_Vehicles!O16 -> 13 | P16: =M16+N16 -> 77
B17: 45939 | C17: Thu | D17: 09:00–10:00 | E17: C&J | F17: =C_Vehicles!F17+J_Vehicles!F17 -> 6 | G17: =C_Vehicles!G17+J_Vehicles!G17 -> 22 | H17: =C_Vehicles!H17+J_Vehicles!H17 -> 12 | I17: =C_Vehicles!I17+J_Vehicles!I17 -> 5 | J17: =C_Vehicles!J17+J_Vehicles!J17 -> 3 | K17: =C_Vehicles!K17+J_Vehicles!K17 -> 3 | L17: =C_Vehicles!L17+J_Vehicles!L17 -> 4 | M17: =SUM(F17:L17) -> 55 | N17: =C_Vehicles!N17+J_Vehicles!N17 -> 38 | O17: =C_Vehicles!O17+J_Vehicles!O17 -> 18 | P17: =M17+N17 -> 93
D18: 14:00–15:00 | E18: C&J | F18: =C_Vehicles!F18+J_Vehicles!F18 -> 9 | G18: =C_Vehicles!G18+J_Vehicles!G18 -> 19 | H18: =C_Vehicles!H18+J_Vehicles!H18 -> 10 | I18: =C_Vehicles!I18+J_Vehicles!I18 -> 2 | J18: =C_Vehicles!J18+J_Vehicles!J18 -> 1 | K18: =C_Vehicles!K18+J_Vehicles!K18 -> 1 | L18: =C_Vehicles!L18+J_Vehicles!L18 -> 2 | M18: =SUM(F18:L18) -> 44 | N18: =C_Vehicles!N18+J_Vehicles!N18 -> 36 | O18: =C_Vehicles!O18+J_Vehicles!O18 -> 13 | P18: =M18+N18 -> 80
B19: 45940 | C19: Fri | D19: 09:00–10:00 | E19: C&J | F19: =C_Vehicles!F19+J_Vehicles!F19 -> 9 | G19: =C_Vehicles!G19+J_Vehicles!G19 -> 19 | H19: =C_Vehicles!H19+J_Vehicles!H19 -> 20 | I19: =C_Vehicles!I19+J_Vehicles!I19 -> 1 | J19: =C_Vehicles!J19+J_Vehicles!J19 -> 3 | K19: =C_Vehicles!K19+J_Vehicles!K19 -> 2 | L19: =C_Vehicles!L19+J_Vehicles!L19 -> 2 | M19: =SUM(F19:L19) -> 56 | N19: =C_Vehicles!N19+J_Vehicles!N19 -> 26 | O19: =C_Vehicles!O19+J_Vehicles!O19 -> 7 | P19: =M19+N19 -> 82
D20: 14:00–15:00 | E20: C&J | F20: =C_Vehicles!F20+J_Vehicles!F20 -> 11 | G20: =C_Vehicles!G20+J_Vehicles!G20 -> 25 | H20: =C_Vehicles!H20+J_Vehicles!H20 -> 23 | I20: =C_Vehicles!I20+J_Vehicles!I20 -> 0 | J20: =C_Vehicles!J20+J_Vehicles!J20 -> 2 | K20: =C_Vehicles!K20+J_Vehicles!K20 -> 3 | L20: =C_Vehicles!L20+J_Vehicles!L20 -> 1 | M20: =SUM(F20:L20) -> 65 | N20: =C_Vehicles!N20+J_Vehicles!N20 -> 32 | O20: =C_Vehicles!O20+J_Vehicles!O20 -> 12 | P20: =M20+N20 -> 97
A21: W2 | B21: 45943 | C21: Mon | D21: 09:00–10:00 | E21: C&J | F21: =C_Vehicles!F21+J_Vehicles!F21 -> 6 | G21: =C_Vehicles!G21+J_Vehicles!G21 -> 16 | H21: =C_Vehicles!H21+J_Vehicles!H21 -> 3 | I21: =C_Vehicles!I21+J_Vehicles!I21 -> 6 | J21: =C_Vehicles!J21+J_Vehicles!J21 -> 2 | K21: =C_Vehicles!K21+J_Vehicles!K21 -> 1 | L21: =C_Vehicles!L21+J_Vehicles!L21 -> 3 | M21: =SUM(F21:L21) -> 37 | N21: =C_Vehicles!N21+J_Vehicles!N21 -> 24 | O21: =C_Vehicles!O21+J_Vehicles!O21 -> 13 | P21: =M21+N21 -> 61
D22: 14:00–15:00 | E22: C&J | F22: =C_Vehicles!F22+J_Vehicles!F22 -> 8 | G22: =C_Vehicles!G22+J_Vehicles!G22 -> 12 | H22: =C_Vehicles!H22+J_Vehicles!H22 -> 2 | I22: =C_Vehicles!I22+J_Vehicles!I22 -> 5 | J22: =C_Vehicles!J22+J_Vehicles!J22 -> 0 | K22: =C_Vehicles!K22+J_Vehicles!K22 -> 2 | L22: =C_Vehicles!L22+J_Vehicles!L22 -> 3 | M22: =SUM(F22:L22) -> 32 | N22: =C_Vehicles!N22+J_Vehicles!N22 -> 18 | O22: =C_Vehicles!O22+J_Vehicles!O22 -> 7 | P22: =M22+N22 -> 50
B23: 45944 | C23: Tue | D23: 09:00–10:00 | E23: C&J | F23: =C_Vehicles!F23+J_Vehicles!F23 -> 7 | G23: =C_Vehicles!G23+J_Vehicles!G23 -> 18 | H23: =C_Vehicles!H23+J_Vehicles!H23 -> 13 | I23: =C_Vehicles!I23+J_Vehicles!I23 -> 3 | J23: =C_Vehicles!J23+J_Vehicles!J23 -> 2 | K23: =C_Vehicles!K23+J_Vehicles!K23 -> 5 | L23: =C_Vehicles!L23+J_Vehicles!L23 -> 4 | M23: =SUM(F23:L23) -> 52 | N23: =C_Vehicles!N23+J_Vehicles!N23 -> 37 | O23: =C_Vehicles!O23+J_Vehicles!O23 -> 13 | P23: =M23+N23 -> 89
D24: 14:00–15:00 | E24: C&J | F24: =C_Vehicles!F24+J_Vehicles!F24 -> 10 | G24: =C_Vehicles!G24+J_Vehicles!G24 -> 20 | H24: =C_Vehicles!H24+J_Vehicles!H24 -> 10 | I24: =C_Vehicles!I24+J_Vehicles!I24 -> 2 | J24: =C_Vehicles!J24+J_Vehicles!J24 -> 3 | K24: =C_Vehicles!K24+J_Vehicles!K24 -> 6 | L24: =C_Vehicles!L24+J_Vehicles!L24 -> 4 | M24: =SUM(F24:L24) -> 55 | N24: =C_Vehicles!N24+J_Vehicles!N24 -> 33 | O24: =C_Vehicles!O24+J_Vehicles!O24 -> 17 | P24: =M24+N24 -> 88
B25: 45945 | C25: Wed | D25: 09:00–10:00 | E25: C&J | F25: =C_Vehicles!F25+J_Vehicles!F25 -> 9 | G25: =C_Vehicles!G25+J_Vehicles!G25 -> 20 | H25: =C_Vehicles!H25+J_Vehicles!H25 -> 8 | I25: =C_Vehicles!I25+J_Vehicles!I25 -> 1 | J25: =C_Vehicles!J25+J_Vehicles!J25 -> 3 | K25: =C_Vehicles!K25+J_Vehicles!K25 -> 2 | L25: =C_Vehicles!L25+J_Vehicles!L25 -> 3 | M25: =SUM(F25:L25) -> 46 | N25: =C_Vehicles!N25+J_Vehicles!N25 -> 36 | O25: =C_Vehicles!O25+J_Vehicles!O25 -> 19 | P25: =M25+N25 -> 82
D26: 14:00–15:00 | E26: C&J | F26: =C_Vehicles!F26+J_Vehicles!F26 -> 8 | G26: =C_Vehicles!G26+J_Vehicles!G26 -> 20 | H26: =C_Vehicles!H26+J_Vehicles!H26 -> 4 | I26: =C_Vehicles!I26+J_Vehicles!I26 -> 2 | J26: =C_Vehicles!J26+J_Vehicles!J26 -> 1 | K26: =C_Vehicles!K26+J_Vehicles!K26 -> 2 | L26: =C_Vehicles!L26+J_Vehicles!L26 -> 0 | M26: =SUM(F26:L26) -> 37 | N26: =C_Vehicles!N26+J_Vehicles!N26 -> 35 | O26: =C_Vehicles!O26+J_Vehicles!O26 -> 13 | P26: =M26+N26 -> 72
B27: 45946 | C27: Thu | D27: 09:00–10:00 | E27: C&J | F27: =C_Vehicles!F27+J_Vehicles!F27 -> 8 | G27: =C_Vehicles!G27+J_Vehicles!G27 -> 21 | H27: =C_Vehicles!H27+J_Vehicles!H27 -> 4 | I27: =C_Vehicles!I27+J_Vehicles!I27 -> 4 | J27: =C_Vehicles!J27+J_Vehicles!J27 -> 3 | K27: =C_Vehicles!K27+J_Vehicles!K27 -> 5 | L27: =C_Vehicles!L27+J_Vehicles!L27 -> 1 | M27: =SUM(F27:L27) -> 46 | N27: =C_Vehicles!N27+J_Vehicles!N27 -> 37 | O27: =C_Vehicles!O27+J_Vehicles!O27 -> 22 | P27: =M27+N27 -> 83
D28: 14:00–15:00 | E28: C&J | F28: =C_Vehicles!F28+J_Vehicles!F28 -> 10 | G28: =C_Vehicles!G28+J_Vehicles!G28 -> 22 | H28: =C_Vehicles!H28+J_Vehicles!H28 -> 4 | I28: =C_Vehicles!I28+J_Vehicles!I28 -> 2 | J28: =C_Vehicles!J28+J_Vehicles!J28 -> 2 | K28: =C_Vehicles!K28+J_Vehicles!K28 -> 3 | L28: =C_Vehicles!L28+J_Vehicles!L28 -> 0 | M28: =SUM(F28:L28) -> 43 | N28: =C_Vehicles!N28+J_Vehicles!N28 -> 35 | O28: =C_Vehicles!O28+J_Vehicles!O28 -> 18 | P28: =M28+N28 -> 78
B29: 45947 | C29: Fri | D29: 09:00–10:00 | E29: C&J | F29: =C_Vehicles!F29+J_Vehicles!F29 -> 9 | G29: =C_Vehicles!G29+J_Vehicles!G29 -> 13 | H29: =C_Vehicles!H29+J_Vehicles!H29 -> 18 | I29: =C_Vehicles!I29+J_Vehicles!I29 -> 1 | J29: =C_Vehicles!J29+J_Vehicles!J29 -> 4 | K29: =C_Vehicles!K29+J_Vehicles!K29 -> 4 | L29: =C_Vehicles!L29+J_Vehicles!L29 -> 1 | M29: =SUM(F29:L29) -> 50 | N29: =C_Vehicles!N29+J_Vehicles!N29 -> 34 | O29: =C_Vehicles!O29+J_Vehicles!O29 -> 16 | P29: =M29+N29 -> 84
D30: 14:00–15:00 | E30: C&J | F30: =C_Vehicles!F30+J_Vehicles!F30 -> 6 | G30: =C_Vehicles!G30+J_Vehicles!G30 -> 16 | H30: =C_Vehicles!H30+J_Vehicles!H30 -> 18 | I30: =C_Vehicles!I30+J_Vehicles!I30 -> 0 | J30: =C_Vehicles!J30+J_Vehicles!J30 -> 3 | K30: =C_Vehicles!K30+J_Vehicles!K30 -> 1 | L30: =C_Vehicles!L30+J_Vehicles!L30 -> 4 | M30: =SUM(F30:L30) -> 48 | N30: =C_Vehicles!N30+J_Vehicles!N30 -> 37 | O30: =C_Vehicles!O30+J_Vehicles!O30 -> 14 | P30: =M30+N30 -> 85
A31: W3 | B31: 45950 | C31: Mon | D31: 09:00–10:00 | E31: C&J | F31: =C_Vehicles!F31+J_Vehicles!F31 -> 11 | G31: =C_Vehicles!G31+J_Vehicles!G31 -> 17 | H31: =C_Vehicles!H31+J_Vehicles!H31 -> 7 | I31: =C_Vehicles!I31+J_Vehicles!I31 -> 6 | J31: =C_Vehicles!J31+J_Vehicles!J31 -> 2 | K31: =C_Vehicles!K31+J_Vehicles!K31 -> 1 | L31: =C_Vehicles!L31+J_Vehicles!L31 -> 4 | M31: =SUM(F31:L31) -> 48 | N31: =C_Vehicles!N31+J_Vehicles!N31 -> 27 | O31: =C_Vehicles!O31+J_Vehicles!O31 -> 14 | P31: =M31+N31 -> 75
D32: 14:00–15:00 | E32: C&J | F32: =C_Vehicles!F32+J_Vehicles!F32 -> 9 | G32: =C_Vehicles!G32+J_Vehicles!G32 -> 15 | H32: =C_Vehicles!H32+J_Vehicles!H32 -> 4 | I32: =C_Vehicles!I32+J_Vehicles!I32 -> 5 | J32: =C_Vehicles!J32+J_Vehicles!J32 -> 2 | K32: =C_Vehicles!K32+J_Vehicles!K32 -> 1 | L32: =C_Vehicles!L32+J_Vehicles!L32 -> 2 | M32: =SUM(F32:L32) -> 38 | N32: =C_Vehicles!N32+J_Vehicles!N32 -> 23 | O32: =C_Vehicles!O32+J_Vehicles!O32 -> 12 | P32: =M32+N32 -> 61
B33: 45951 | C33: Tue | D33: 09:00–10:00 | E33: C&J | F33: =C_Vehicles!F33+J_Vehicles!F33 -> 7 | G33: =C_Vehicles!G33+J_Vehicles!G33 -> 20 | H33: =C_Vehicles!H33+J_Vehicles!H33 -> 5 | I33: =C_Vehicles!I33+J_Vehicles!I33 -> 4 | J33: =C_Vehicles!J33+J_Vehicles!J33 -> 5 | K33: =C_Vehicles!K33+J_Vehicles!K33 -> 0 | L33: =C_Vehicles!L33+J_Vehicles!L33 -> 1 | M33: =SUM(F33:L33) -> 42 | N33: =C_Vehicles!N33+J_Vehicles!N33 -> 29 | O33: =C_Vehicles!O33+J_Vehicles!O33 -> 13 | P33: =M33+N33 -> 71
D34: 14:00–15:00 | E34: C&J | F34: =C_Vehicles!F34+J_Vehicles!F34 -> 7 | G34: =C_Vehicles!G34+J_Vehicles!G34 -> 20 | H34: =C_Vehicles!H34+J_Vehicles!H34 -> 4 | I34: =C_Vehicles!I34+J_Vehicles!I34 -> 3 | J34: =C_Vehicles!J34+J_Vehicles!J34 -> 4 | K34: =C_Vehicles!K34+J_Vehicles!K34 -> 1 | L34: =C_Vehicles!L34+J_Vehicles!L34 -> 4 | M34: =SUM(F34:L34) -> 43 | N34: =C_Vehicles!N34+J_Vehicles!N34 -> 31 | O34: =C_Vehicles!O34+J_Vehicles!O34 -> 13 | P34: =M34+N34 -> 74
B35: 45952 | C35: Wed | D35: 09:00–10:00 | E35: C&J | F35: =C_Vehicles!F35+J_Vehicles!F35 -> 10 | G35: =C_Vehicles!G35+J_Vehicles!G35 -> 18 | H35: =C_Vehicles!H35+J_Vehicles!H35 -> 6 | I35: =C_Vehicles!I35+J_Vehicles!I35 -> 2 | J35: =C_Vehicles!J35+J_Vehicles!J35 -> 2 | K35: =C_Vehicles!K35+J_Vehicles!K35 -> 3 | L35: =C_Vehicles!L35+J_Vehicles!L35 -> 0 | M35: =SUM(F35:L35) -> 41 | N35: =C_Vehicles!N35+J_Vehicles!N35 -> 40 | O35: =C_Vehicles!O35+J_Vehicles!O35 -> 15 | P35: =M35+N35 -> 81
D36: 14:00–15:00 | E36: C&J | F36: =C_Vehicles!F36+J_Vehicles!F36 -> 7 | G36: =C_Vehicles!G36+J_Vehicles!G36 -> 21 | H36: =C_Vehicles!H36+J_Vehicles!H36 -> 6 | I36: =C_Vehicles!I36+J_Vehicles!I36 -> 4 | J36: =C_Vehicles!J36+J_Vehicles!J36 -> 0 | K36: =C_Vehicles!K36+J_Vehicles!K36 -> 3 | L36: =C_Vehicles!L36+J_Vehicles!L36 -> 1 | M36: =SUM(F36:L36) -> 42 | N36: =C_Vehicles!N36+J_Vehicles!N36 -> 30 | O36: =C_Vehicles!O36+J_Vehicles!O36 -> 9 | P36: =M36+N36 -> 72
B37: 45953 | C37: Thu | D37: 09:00–10:00 | E37: C&J | F37: =C_Vehicles!F37+J_Vehicles!F37 -> 6 | G37: =C_Vehicles!G37+J_Vehicles!G37 -> 24 | H37: =C_Vehicles!H37+J_Vehicles!H37 -> 3 | I37: =C_Vehicles!I37+J_Vehicles!I37 -> 5 | J37: =C_Vehicles!J37+J_Vehicles!J37 -> 4 | K37: =C_Vehicles!K37+J_Vehicles!K37 -> 2 | L37: =C_Vehicles!L37+J_Vehicles!L37 -> 3 | M37: =SUM(F37:L37) -> 47 | N37: =C_Vehicles!N37+J_Vehicles!N37 -> 35 | O37: =C_Vehicles!O37+J_Vehicles!O37 -> 21 | P37: =M37+N37 -> 82
D38: 14:00–15:00 | E38: C&J | F38: =C_Vehicles!F38+J_Vehicles!F38 -> 5 | G38: =C_Vehicles!G38+J_Vehicles!G38 -> 22 | H38: =C_Vehicles!H38+J_Vehicles!H38 -> 5 | I38: =C_Vehicles!I38+J_Vehicles!I38 -> 4 | J38: =C_Vehicles!J38+J_Vehicles!J38 -> 2 | K38: =C_Vehicles!K38+J_Vehicles!K38 -> 3 | L38: =C_Vehicles!L38+J_Vehicles!L38 -> 4 | M38: =SUM(F38:L38) -> 45 | N38: =C_Vehicles!N38+J_Vehicles!N38 -> 35 | O38: =C_Vehicles!O38+J_Vehicles!O38 -> 19 | P38: =M38+N38 -> 80
B39: 45954 | C39: Fri | D39: 09:00–10:00 | E39: C&J | F39: =C_Vehicles!F39+J_Vehicles!F39 -> 10 | G39: =C_Vehicles!G39+J_Vehicles!G39 -> 16 | H39: =C_Vehicles!H39+J_Vehicles!H39 -> 14 | I39: =C_Vehicles!I39+J_Vehicles!I39 -> 5 | J39: =C_Vehicles!J39+J_Vehicles!J39 -> 1 | K39: =C_Vehicles!K39+J_Vehicles!K39 -> 4 | L39: =C_Vehicles!L39+J_Vehicles!L39 -> 1 | M39: =SUM(F39:L39) -> 51 | N39: =C_Vehicles!N39+J_Vehicles!N39 -> 8 | O39: =C_Vehicles!O39+J_Vehicles!O39 -> 2 | P39: =M39+N39 -> 59
D40: 14:00–15:00 | E40: C&J | F40: =C_Vehicles!F40+J_Vehicles!F40 -> 8 | G40: =C_Vehicles!G40+J_Vehicles!G40 -> 14 | H40: =C_Vehicles!H40+J_Vehicles!H40 -> 12 | I40: =C_Vehicles!I40+J_Vehicles!I40 -> 5 | J40: =C_Vehicles!J40+J_Vehicles!J40 -> 1 | K40: =C_Vehicles!K40+J_Vehicles!K40 -> 4 | L40: =C_Vehicles!L40+J_Vehicles!L40 -> 3 | M40: =SUM(F40:L40) -> 47 | N40: =C_Vehicles!N40+J_Vehicles!N40 -> 12 | O40: =C_Vehicles!O40+J_Vehicles!O40 -> 2 | P40: =M40+N40 -> 59
...
